Workbook
Name _REN60: '[1]imp g.o.'!#REF!
Name _UVT2010: #REF!
Name ANEXOS: #REF!
Name ANEXOS4: #REF!
Name BALANCE1: #REF!
Name COD_REPRES: #N/A
Name dirmanualuser: #REF!
Name ESTADO: #REF!
Name SALDOS: #REF!
Name validalog: #REF!

Sheet Índice
B2: Tributando.co
B3: Papeles de trabajo — Declaración de Renta · Formulario 210
B5: 🧾 Formulario 210 (autoritativo)
B6: 📄 Exógena 2025 — reportada por terceros
B7: 🏠 Patrimonio bruto
B8: 💳 Deudas
B9: 💼 Rentas de trabajo y honorarios
B10: 🏦 Rentas de capital
B11: 📦 Rentas no laborales y gravables
B12: 👴 Cédula de pensiones
B13: 📈 Dividendos
B14: 🎯 Ganancias ocasionales
... B20: Clic en una sección para ir directo. Los valores en dorado itálica provienen de la entrevista/app; el resto, de la exógena DIAN.

Sheet Calendario Tributario
A1: DECLARACIÓN DE RENTA Y COMPLEMENTARIOS
A3: Personas naturales y sucesiones ilíquidas
A5: Declaración y pago
A7: Últimos 2 dígito del NIT | B7: Fecha límite | D7: Últimos 2 dígito del NIT | E7: Fecha límite | G7: Últimos 2 dígito del NIT | H7: Fecha límite | J7: Últimos 2 dígito del NIT | K7: Fecha límite | M7: Últimos 2 dígito del NIT | N7: Fecha límite
A8: 01 Y 02 | B8: 46246 | D8: 21 Y 22 | E8: 46261 | G8: 41 Y 42 | H8: 46275 | J8: 61 Y 62 | K8: 46289 | M8: 81 Y 82 | N8: 46308
A9: 03 Y 04 | B9: 46247 | D9: 23 Y 24 | E9: 46262 | G9: 43 Y 44 | H9: 46276 | J9: 63 Y 64 | K9: 45925 | M9: 83 Y 84 | N9: 46309
A10: 05 Y 06 | B10: 46248 | D10: 25 Y 26 | E10: 46265 | G10: 45 Y 46 | H10: 46279 | J10: 65 Y 66 | K10: 46293 | M10: 85 Y 86 | N10: 46310
A11: 07 Y 08 | B11: 46252 | D11: 27 Y 28 | E11: 46266 | G11: 47 Y 48 | H11: 46280 | J11: 67 Y 68 | K11: 46296 | M11: 87 Y 88 | N11: 46311
A12: 09 Y 10 | B12: 46253 | D12: 29 Y 30 | E12: 46267 | G12: 49 Y 50 | H12: 46281 | J12: 69 Y 70 | K12: 46297 | M12: 89 Y 90 | N12: 46314
A13: 11 Y 12 | B13: 46254 | D13: 31 Y 32 | E13: 46268 | G13: 51 Y 52 | H13: 46282 | J13: 71 Y 72 | K13: 46300 | M13: 91 Y 92 | N13: 46315
A14: 13 Y 14 | B14: 46255 | D14: 33 Y 34 | E14: 46269 | G14: 53 Y 54 | H14: 46283 | J14: 73 Y 74 | K14: 46301 | M14: 93 Y 94 | N14: 46316
A15: 15 Y 16 | B15: 46258 | D15: 35 Y 36 | E15: 46272 | G15: 55 Y 56 | H15: 46286 | J15: 75 Y 76 | K15: 46302 | M15: 95 Y 96 | N15: 46317
A16: 17 Y 18 | B16: 46259 | D16: 37 Y 38 | E16: 46273 | G16: 57 Y 58 | H16: 46287 | J16: 77 Y 78 | K16: 46303 | M16: 97 Y 98 | N16: 46318
A17: 19 Y 20 | B17: 46260 | D17: 39 Y 40 | E17: 46274 | G17: 59 Y 60 | H17: 46288 | J17: 79 Y 80 | K17: 46304 | M17: 99 Y 00 | N17: 46321
B21: 01 | C21: 46246
B22: 02 | C22: 46246
B23: 03 | C23: 46247
B24: 04 | C24: 46247
B25: 05 | C25: 46248
B26: 06 | C26: 46248
B27: 07 | C27: 46252
B28: 08 | C28: 46252
B29: 09 | C29: 46253
B30: 10 | C30: 46253
B31: 11 | C31: 46254
B32: 12 | C32: 46254
... B120: 00 | C120: 46321

Sheet Datos del contribuyente
B6: Numero de identificación tributaria
B7: DV
B8: Primer apellido
B9: Segundo apellido
B10: Primer Nombre
B11: Otros Nombres
B12: Actividad Económica
B13: Corrección - De ser afirmativo marque x
B14: No. formulario Anterior
B15: Fecha de presentación | C15: =VLOOKUP(RIGHT(C6,2),'Calendario Tributario'!$B$21:$C$120,2,0) | D15: No digitar fecha - Automático

Sheet FORMULARIO 210
G2: Declaración de renta y complementarios personas naturales y asimiladas residentes y sucesiones ilíquidas de causantes residentes | AA2: 210 | AH2: Concepto | AI2: Reng | AJ2: Valor
AH3: Ingresos brutos por rentas de trabajo | AJ3: =H15
AH4: Ingreso Rentas por honorarios | AJ4: =M15
AH5: Ingresos brutos por rentas de capital | AJ5: =S15
B6: ACCESO: | P6: CLAVE FIRMA: | AH6: Ingresos brutos por rentas no laborales | AJ6: =Z15
AH7: Total ingresos brutos | AJ7: =SUM(AJ3:AJ6)
AH8: (-) I.N.C.R.N.G.O. | AJ8: =H17
B9: Datos declarante | C9: 5. Numero de identificación tributaria (NIT) | K9: 6. DV | L9: 7. Primer apellido | Q9: 8. Segundo apellido | V9: 9. Primer nombre | Z9: 10. Otros nombres | AB9: 12. Cod Dir | AH9: (-) I.N.C.R.N.G.O. | AJ9: =M17
C10: ='Datos del contribuyente'!C6 | K10: ='Datos del contribuyente'!C7 | L10: ='Datos del contribuyente'!C8 | Q10: ='Datos del contribuyente'!C9 | V10: ='Datos del contribuyente'!C10 | Z10: ='Datos del contribuyente'!C11 | AH10: (-) I.N.C.R.N.G.O. | AJ10: =S17
AH11: (-) I.N.C.R.N.G.O. | AJ11: =Z17
B12: 24. Actividad economica | F12: ='Datos del contribuyente'!C12 | G12: Si es una correción indique: 25. Cod | J12: ='Datos del contribuyente'!C13 | K12: 26. N° del formulario anterior | O12: ='Datos del contribuyente'!C14 | P12: 27. fraccion año gravable siguiente | W12: 28. Uno porciento (1%) de compras con factura electronica | AB12: 0
B13: Patrimonio | F13: Patrimonio bruto | K13: 29 | L13: 0 | P13: Deudas | R13: 30 | S13: 0 | V13: Total patrimonio líquido | Y13: 31 | Z13: 0 | AH13: (-) Devoluciones, rebajas, descuentos | AJ13: =+Z16
B14: Cédula general | C14: Conceptos / renta | G14: Rentas de trabajo | L14: Rentas de trabajo que no provengan de una relacion laboral o legal y reglamentaria | R14: Rentas de capital | Y14: Rentas no laborales | AH14: (-) Rentas exentas no limitadas | AJ14: ='R.trabajo y honorarios'!F54+'R.trabajo y honorarios'!G58+'R.trabajo y honorarios'!G59+'R.trabajo y honorarios'!G60+'R.trabajo y honorarios'!G61+'R.no laboral y R gravables'!F66
C15: Ingresos brutos | G15: 32 | H15: 0 | L15: 43 | M15: 0 | R15: 58 | S15: 0 | Y15: 74 | Z15: 0 | AH15: (=) Base límite del 40% | AJ15: =AJ7-AJ8-AJ9-AJ10-AJ13-AJ14-AJ11
C16: Devoluciones, rebajas y descuentos | Y16: 75 | Z16: 0 | AH16: (A) Monto de las rentas exenta y deducciones limitadas - 40% | AJ16: =AJ15*0.4
C17: Ingresos no constitutivos de renta | G17: 33 | H17: 0 | L17: 44 | M17: 0 | R17: 59 | S17: 0 | Y17: 76 | Z17: 0 | AH17: (B) Maximo 1.340 UVT | AJ17: =ROUND('R.trabajo y honorarios'!H74*1340,-3)
C18: Costos y deducciones procedentes | L18: 45 | M18: 0 | R18: 60 | S18: 0 | Y18: 77 | Z18: 0 | AH18: (menor entre A y B) Rentas exentas y deducciones limitadas | AJ18: =MIN(AJ17,AJ16)
C19: Renta líquida | G19: 34 | H19: 0 | L19: 46 | M19: 0 | R19: 61 | S19: 0 | Y19: 78 | Z19: 0 | AH19: (+) Renta exentas no limitadas | AJ19: =AJ14
C20: Rentas líquidas pasivas - ECE | R20: 62 | S20: 0 | Y20: 79 | Z20: 0 | AH20: (=) Rentas exentas y deducciones limitadas definitivas | AJ20: =SUM(AJ18:AJ19) | AK20: total
C21: Rentas exentas | D21: Aportes voluntarios AFC, FVP y/o AVC | G21: 35 | H21: 0 | L21: 47 | M21: 0 | R21: 63 | S21: 0 | Y21: 80 | Z21: 0 | AH21: Rentas exentas y deducciones - Rentas de trabajo | AJ21: =H26+H23
D22: Otras rentas exentas | G22: 36 | H22: 0 | L22: 48 | M22: 0 | R22: 64 | S22: 0 | Y22: 81 | Z22: 0 | AH22: Rentas exentas y deducciones - Rentas de trabajo (limitadas) | AJ22: =MIN(AJ21,AJ20)
D23: Total rentas exentas | G23: 37 | H23: 0 | L23: 49 | M23: 0 | R23: 65 | S23: 0 | Y23: 82 | Z23: 0 | AH23: Rentas exentas por distribuir | AJ23: =AJ20-AJ22 | AQ23: r. trabajo | AR23: =H15
C24: Deducciones imputables | D24: Intereses de vivienda | G24: 38 | H24: 0 | L24: 50 | M24: 0 | R24: 66 | S24: 0 | Y24: 83 | Z24: 0 | AH24: Rentas exentas y deducciones - Honorarios | AJ24: =M23+M26 | AQ24: r. capital | AR24: =S15
D25: Otras deducciones imputables | G25: 39 | H25: 0 | L25: 51 | M25: 0 | R25: 67 | S25: 0 | Y25: 84 | Z25: 0 | AH25: Rentas exentas y deducciones - Honorarios (limitadas) | AJ25: =MIN(AJ24,AJ23) | AQ25: r. no laboral | AR25: =Z15
D26: Total deducciones imputables | G26: 40 | H26: 0 | L26: 52 | M26: 0 | R26: 68 | S26: 0 | Y26: 85 | Z26: 0 | AH26: Rentas exentas por distribuir | AJ26: =AJ23-AJ25 | AQ26: C. dividendos | AR26: =J39+J42+J43
C27: Rentas exentas y/o deducciones imputables (limitadas) | G27: 41 | H27: 0 | L27: 53 | M27: 0 | R27: 69 | S27: 0 | Y27: 86 | Z27: 0 | AH27: Rentas exentas y deducciones - Rentas de capital | AJ27: =S23+S26 | AQ27: g. ocasional | AR27: =J47
C28: Renta líquida ordinaria del ejercicio | L28: 54 | M28: 0 | R28: 70 | S28: 0 | Y28: 87 | Z28: 0 | AH28: Rentas exentas y deducciones - Rentas de capital (limitadas) | AJ28: =ROUND(IF(AJ23>AJ27,AJ27,AJ23),-3) | AQ28: total | AR28: =SUM(AR23:AR27)
C29: Pérdida líquida del ejercicio | L29: 55 | M29: 0 | R29: 71 | S29: 0 | Y29: 88 | Z29: 0 | AH29: Rentas exentas por distribuir | AJ29: =AJ26-AJ28
C30: Compensaciones por pérdidas | L30: 56 | M30: 0 | R30: 72 | S30: 0 | Y30: 89 | Z30: 0 | AH30: Rentas exentas y deducciones - Rentas no laborales | AJ30: =Z23+Z26 | AQ30: R capital y no labo | AR30: =AR25+AR24
C31: Renta líquida ordinaria | G31: 42 | H31: 0 | L31: 57 | M31: 0 | R31: 73 | S31: 0 | Y31: 90 | Z31: 0 | AH31: Rentas exentas y deducciones - Rentas no laborales (limitadas) | AJ31: =ROUND(IF(AJ29>AJ30,AJ30,AJ29),-3)
C32: Ren. líquida céd. gen. | E32: 91 | F32: 0 | I32: Ren. ex. y ded. Imp. Li. | K32: 92 | L32: 0 | P32: R. liq. ord. cédula gen. | R32: 93 | S32: 0 | W32: Comp. Pérdidas año 2018 y ant. | Z32: 94 | AA32: 0
C33: Comp. por exc. renta presuntiva | E33: 95 | F33: 0 | I33: Rentas gravables | K33: 96 | L33: 0 | P33: R. liq. grav. cédula gen. | R33: 97 | S33: 0 | W33: Renta presuntiva | Z33: 98 | AA33: 0
B34: Cédula de pensiones | C34: Ingresos brutos por rentas de pensiones del país y del exterior | I34: 99 | J34: 0 | P34: Liquidación privada | Q34: Impuesto sobre las rentas líquidas gravables | R34: Cédula general, de pensiones y de dividendos y participaciones | X34: 116 | Y34: 0
C35: Ingresos no constitutivos de renta | I35: 100 | J35: 0 | R35: Renta presuntiva, de pensiones y de dividendos y participaciones | X35: 117 | Y35: 0
C36: Renta líquida | I36: 101 | J36: 0 | R36: Por dividendos y partipaciones año 2017 y siguientes, 1a. subcédula | X36: 118 | Y36: 0
C37: Rentas exentas de pensiones | I37: 102 | J37: 0 | R37: Por dividendos y partipaciones año 2016 | X37: 119 | Y37: 0
C38: Renta líquida gravable cédula de pensiones | I38: 103 | J38: 0 | R38: Por dividendos y partipaciones recibidas del exterior | X38: 120 | Y38: 0
B39: Cédula de dividendos y participaciones | C39: Dividendos y participaciones 2016 y anteriores y otros | I39: 104 | J39: 0 | R39: Total impuestos sobre las rentas líquidas gravables | X39: 121 | Y39: 0
C40: Ingresos no constitutivos de renta | I40: 105 | J40: 0 | Q40: Descuentos tributarios | R40: Imp. Pagados en el exterior | T40: 122 | U40: 0 | X40: Donaciones | AA40: 123 | AB40: 0
C41: Renta líquida ordinaria año 2016 y anteriores | I41: 106 | J41: 0 | R41: Dividendos, partic y otros | T41: 124 | U41: 0 | X41: Total des- cuentos trib. | AA41: 125 | AB41: 0
...

Sheet rta x comp patr
B1: Renta Líquida por Comparación Patrimonial
B2: Procedimiento para su Determinación
B3: Concepto | C3: Valores
B4: Patrimonio líquido del año gravable corriente | C4: ='FORMULARIO 210'!Z13
A5: ( + ) | B5: Desvalorizaciones | C5: 0
A6: ( - ) | B6: Valorizaciones | C6: ='Pat bruto'!H119
A7: ( - ) | B7: Patrimonio líquido del año gravable anterior | C7: ='renta presunt'!E6
A8: ( = ) | B8: Variación por comparación patrimonial | C8: =IF(C4+C5-C6-C7>0,C4+C5-C6-C7,0)
B9: Posteriormente
B10: Ajuste de las Rentas
B11: Valor de las Rentas líquidas Cedulares antes de compensaciones | C11: ='FORMULARIO 210'!S32+'FORMULARIO 210'!J38+'FORMULARIO 210'!J41+'FORMULARIO 210'!J42+'FORMULARIO 210'!J43+'FORMULARIO 210'!J44
A12: ( + ) | B12: Rentas exentas (sin límite) y ganancias ocasionales exentas y no gravadas | C12: ='FORMULARIO 210'!H23+'FORMULARIO 210'!M23+'FORMULARIO 210'!S23+'FORMULARIO 210'!Z23+'FORMULARIO 210'!J37+'FORMULARIO 210'!J45+'FORMULARIO 210'!J50
A13: ( + ) | B13: Ingresos no constitutivos de renta ni ganancia ocasional | C13: ='FORMULARIO 210'!H17+'FORMULARIO 210'!M17+'FORMULARIO 210'!S17+'FORMULARIO 210'!Z17+'FORMULARIO 210'!J35+'FORMULARIO 210'!J40
A14: ( + ) | B14: Ganancias ocasionales netas (ingreso por ganancia ocasional - costos por ganancia ocasional) | C14: 0
A15: ( - ) | B15: Impuestos y anticipos pagados en el año gravable
A16: ( - ) | B16: Retenciones en la fuente practicadas en el año gravable | C16: ='FORMULARIO 210'!Y48
A17: ( = ) | B17: Valor de las rentas ajustadas | C17: =((C11+'rta x comp patr'!C12+C13+C14)-(C15+C16))
B18: Resultado
B19: Variación por comparacion patrimonial | C19: =+C8
B20: Valor rentas ajustadas | C20: =IF(OR(C11<0,ISTEXT(C11),'rta x comp patr'!C12<0,ISTEXT('rta x comp patr'!C12),C13<0,ISTEXT(C13),C14<0,ISTEXT(C14),C15<0,ISTEXT(C15),C16<0,ISTEXT(C16)), "Por favor ingrese valores positivos en la celdas B18 a B23.",C11+'rta x comp patr'!C12+C13+C14-C15-C16)
B21: Incremento patrimonial no justificado | C21: =IF(C19>C20,C19-C20,0)
B22: =IF(C20>C19,B27,IF(C20<C19,B29,IF(C20=C19,B25,0)))
B24: Variación patrimonial = Rentas ajustadas
B25: Esta es la situación ideal, ya que se ve reflejado de manera clara los ingresos con los cuales fue posible comprar bienes y derechos que incrementaron el patrimonio líquido. No hay renta por comparación patrimonial
B26: Variación patrimonial < Rentas ajustadas
B27: Esta situación también es buena para el contribuyente ya que la Autoridad Fiscal no cuestiona el porque no se invirtieron todos los ingresos en activos para incrementar el patrimonio líquido. No hay renta por comparación patrimonial
B28: Variación patrimonial > Rentas ajustadas
B29: A esta situación es que la DIAN le prestará especial atención, ya que en el orden de las cosas, se necesitan ingresos para poder comprar bienes o derechos. Al ser las rentas ajustadas inferiores a la variación presentada en el patrimonio, no existe a primera vista, una justificación del incremento. Hay renta por comparación patrimonial

Sheet Hoja1
F4: Año de adquisición | G4: Acciones y Aportes | H4: Bienes Raíces
F5: Multiplicar por
F6: 1955 y anteriores | G6: 3581.32 | H6: 32137.12
F7: 1956 | G7: 3509.63 | H7: 31494.78
F8: 1957 | G8: 3249.68 | H8: 29162.19
F9: 1958 | G9: 2741.82 | H9: 24604.31
F10: 1959 | G10: 2506.66 | H10: 22494.25
F11: 1960 | G11: 2339.61 | H11: 20994.94
F12: 1961 | G12: 2193.32 | H12: 19576.13
F13: 1962 | G13: 2064.46 | H13: 18525.04
F14: 1963 | G14: 1928.23 | H14: 17303.51
F15: 1964 | G15: 1474.42 | H15: 13231.72
F16: 1965 | G16: 1349.81 | H16: 12112.77
F17: 1966 | G17: 1177.62 | H17: 10567.7
F18: 1967 | G18: 1038.26 | H18: 9317.76
... F72: 2021 | G72: 1.06 | H72: 1.03

Sheet Pat bruto
B2: PATRIMONIO BRUTO (Renglón 29)
B4: ENTIDADES FINANCiERAS, FONDOS CESANTIAS, ETC | D4: SALDO 31 DE DICIEMBRE
B29: TOTAL ENTIDADES FINANCIERAS Y CESANTÍAS | D29: =SUM(D5:D28)
B32: CUENTAS POR COBRAR, INVENTARIOS: | D32: SALDO 31 DE DICIEMBRE
B58: CUENTAS POR COBRAR | D58: =SUM(D33:D57)
B61: ACCIONES, APORTES EN SOCIDADES
B62: Descripción | C62: Reajuste fiscal | D62: Costo fiscal a Dic. 31 de 2024 | E62: Costo de compra en el año 2025 | F62: Reajuste fiscal 2025 5,81% Dec. 0049/2026 | G62: Valor patrimonial a Dic. 31 de 2025 | H62: Valorización año 2025
C63: No | F63: =IF(C63>"No",D63*$D$121,0) | G63: =SUM(D63:F63) | H63: =G63-E63-D63
C64: No | F64: =IF(C64>"No",D64*$D$121,0) | G64: =SUM(D64:F64) | H64: =G64-E64-D64
C65: No | F65: =IF(C65>"No",D65*$D$121,0) | G65: =SUM(D65:F65) | H65: =G65-E65-D65
C66: No | F66: =IF(C66>"No",D66*$D$121,0) | G66: =SUM(D66:F66) | H66: =G66-E66-D66
C67: No | F67: =IF(C67>"No",D67*$D$121,0) | G67: =SUM(D67:F67) | H67: =G67-E67-D67
C68: No | F68: =IF(C68>"No",D68*$D$121,0) | G68: =SUM(D68:F68) | H68: =G68-E68-D68
C69: No | F69: =IF(C69>"No",D69*$D$121,0) | G69: =SUM(D69:F69) | H69: =G69-E69-D69
C70: No | F70: =IF(C70>"No",D70*$D$121,0) | G70: =SUM(D70:F70) | H70: =G70-E70-D70
C71: No | F71: =IF(C71>"No",D71*$D$121,0) | G71: =SUM(D71:F71) | H71: =G71-E71-D71
C72: No | F72: =IF(C72>"No",D72*$D$121,0) | G72: =SUM(D72:F72) | H72: =G72-E72-D72
C73: No | F73: =IF(C73>"No",D73*$D$121,0) | G73: =SUM(D73:F73) | H73: =G73-E73-D73
C74: No | F74: =IF(C74>"No",D74*$D$121,0) | G74: =SUM(D74:F74) | H74: =G74-E74-D74
... C78: No | F78: =IF(C78>"No",D78*$D$121,0) | G78: =SUM(D78:F78) | H78: =G78-E78-D78
B79: Valor Patrimonial a Diciembre 31 de 2024 y Valorización | G79: =SUM(G63:G78) | H79: =SUM(H63:H78)
B82: ACTIVOS FIJOS Y OTROS ACTIVOS - OPCIÓN 1
B83: Descripción | C83: Reajuste fiscal | D83: Costo fiscal a Dic. 31 de 2024 | E83: Costo de compra (y/o mejoras, val. pagadas) del 2025 | F83: Reajuste fiscal 2025 5,81% Dec. 0049/2026 | G83: Costo fiscal a Dic. 31 de 2025 | H83: Avaluo Catastral o Auto avaluo catastral 2025 | I83: Valor patrimonial a Dic. 31 de 2025 | J83: Valorización año 2025
C84: No | F84: =IF(C84>"No",D84*$D$121,0) | G84: =SUM(D84:F84) | I84: =IF(H84>G84,H84,G84) | J84: =I84-E84-D84
C85: No | F85: =IF(C85>"No",D85*$D$121,0) | G85: =SUM(D85:F85) | I85: =IF(H85>G85,H85,G85) | J85: =I85-E85-D85
C86: No | F86: =IF(C86>"No",D86*$D$121,0) | G86: =SUM(D86:F86) | I86: =IF(H86>G86,H86,G86) | J86: =I86-E86-D86
C87: No | F87: =IF(C87>"No",D87*$D$121,0) | G87: =SUM(D87:F87) | I87: =IF(H87>G87,H87,G87) | J87: =I87-E87-D87
C88: No | F88: =IF(C88>"No",D88*$D$121,0) | G88: =SUM(D88:F88) | I88: =IF(H88>G88,H88,G88) | J88: =I88-E88-D88
C89: No | F89: =IF(C89>"No",D89*$D$121,0) | G89: =SUM(D89:F89) | I89: =IF(H89>G89,H89,G89) | J89: =I89-E89-D89
C90: No | F90: =IF(C90>"No",D90*$D$121,0) | G90: =SUM(D90:F90) | I90: =IF(H90>G90,H90,G90) | J90: =I90-E90-D90
C91: No | F91: =IF(C91>"No",D91*$D$121,0) | G91: =SUM(D91:F91) | I91: =IF(H91>G91,H91,G91) | J91: =I91-E91-D91
C92: No | F92: =IF(C92>"No",D92*$D$121,0) | G92: =SUM(D92:F92) | I92: =IF(H92>G92,H92,G92) | J92: =I92-E92-D92
C93: No | F93: =IF(C93>"No",D93*$D$121,0) | G93: =SUM(D93:F93) | I93: =IF(H93>G93,H93,G93) | J93: =I93-E93-D93
C94: No | F94: =IF(C94>"No",D94*$D$121,0) | G94: =SUM(D94:F94) | I94: =IF(H94>G94,H94,G94) | J94: =I94-E94-D94
C95: No | F95: =IF(C95>"No",D95*$D$121,0) | G95: =SUM(D95:F95) | I95: =IF(H95>G95,H95,G95) | J95: =I95-E95-D95
... C100: No | F100: =IF(C100>"No",D100*$D$121,0) | G100: =SUM(D100:F100) | I100: =IF(H100>G100,H100,G100) | J100: =I100-E100-D100
B101: Valor Patrimonial a Diciembre 31 de 2024 y Valorización | I101: =SUM(I84:I100) | J101: =SUM(J84:J100)
B104: ACTIVOS FIJOS Y ACCIONES OPCIÓN 2 ART. 73 E.T.
B105: Descripción | C105: Costo fiscal a Dic. 31 de 2024 | D105: Costo original de adquisición | E105: BIENES RAICES O ACCIONES | F105: FECHA DE ADQUISICIÓN | G105: Factor según tabla art. 73 E.T. (Art. 1 Dec. 0049 2026) | H105: Total costo fiscal Dic. 31 de 2025 | I105: Valorización año 2025
G106: =IF('Pat bruto'!E106="ACCIONES",VLOOKUP('Pat bruto'!F106,Sheet1!$B$5:$F$75,2),IF('Pat bruto'!E106="BIENES URBANOS",VLOOKUP('Pat bruto'!F106,Sheet1!$B$5:$F$75,3),IF('Pat bruto'!E106="BIENES RURALES",VLOOKUP('Pat bruto'!F106,Sheet1!$B$5:$F$75,5),IF('Pat bruto'!E106="Bienes Raíces Rurales dedicados a actividades agropecuarias",VLOOKUP('Pat bruto'!F106,Sheet1!$B$5:$F$75,4),0)))) | H106: =D106*'Pat bruto'!G106 | I106: =+H106-C106
...

Sheet EXOGENA 2025

Sheet Sheet1
E2: UVT | F2: ='R.trabajo y honorarios'!H74
C3: =#REF!
B5: Año | C5: Acciones y aportes | D5: Bienes urbanos | E5: Bienes Raíces Rurales dedicados a actividades agropecuarias | F5: Bienes Rurales | I5: =42412*L7 | R5: Aportes voluntarios - Renta de trabajo | U5: exentas al 25%
B6: 1955 y anteriores | C6: 4664.64 | D6: 36085.1 | E6: 34963.67 | F6: 35631.92 | H6: Renta de trabajo - censantias y intereses | R6: Limite 3.800 UVT | S6: ='R.trabajo y honorarios'!H74*3800 | U6: =240*12
B7: 1956 | C7: 4571.26 | D7: 35363.86 | E7: 34264.84 | F7: 34919.74 | H7: Entre | I7: =L7*'R.trabajo y honorarios'!$H$74 | J7: Y | K7: =O7*'R.trabajo y honorarios'!$H$74 | L7: 350 | M7: UVT | N7: Y | O7: 410 | P7: 0.9 | R7: Limite ingresos | S7: ='R.trabajo y honorarios'!H4*30% | U7: =U6*'R.trabajo y honorarios'!H74
B8: 1957 | C8: 4232.67 | D8: 32744.71 | E8: 31727.09 | F8: 32333.48 | H8: Entre | I8: =L8*'R.trabajo y honorarios'!$H$74 | J8: Y | K8: =O8*'R.trabajo y honorarios'!$H$74 | L8: 410 | M8: UVT | N8: Y | O8: 470 | P8: 0.8 | R8: Valor reportado | S8: ='R.trabajo y honorarios'!F50+'R.trabajo y honorarios'!F51
B9: 1958 | C9: 3571.2 | D9: 27626.91 | E9: 26768.34 | F9: 27279.95 | H9: Entre | I9: =L9*'R.trabajo y honorarios'!$H$74 | J9: Y | K9: =O9*'R.trabajo y honorarios'!$H$74 | L9: 470 | M9: UVT | N9: Y | O9: 530 | P9: 0.6 | R9: Valor a reportar | S9: =MIN(S6:S8)
B10: 1959 | C10: 3264.9 | D10: 25257.62 | E10: 24472.68 | F10: 24940.42 | H10: Entre | I10: =L10*'R.trabajo y honorarios'!$H$74 | J10: Y | K10: =O10*'R.trabajo y honorarios'!$H$74 | L10: 530 | M10: UVT | N10: Y | O10: 590 | P10: 0.4 | U10: INCRNGO
B11: 1960 | C11: 3047.31 | D11: 23574.13 | E11: 22841.51 | F11: 23278.07 | H11: Entre | I11: =L11*'R.trabajo y honorarios'!$H$74 | J11: Y | K11: =O11*'R.trabajo y honorarios'!$H$74 | L11: 590 | M11: UVT | N11: Y | O11: 650 | P11: 0.2 | U11: Aporte voluntario a fondo obligatorio porvenir - RAIS - Renta de trabajo | V11: Aporte voluntario a fondo obligatorio porvenir - RAIS - Honorarios | W11: Aporte voluntario a fondo obligatorio porvenir - RAIS - Renta de capital | X11: Aporte voluntario a fondo obligatorio porvenir - RAIS - Renta no laboral | Y11: ,
B12: 1961 | C12: 2856.78 | D12: 21981.02 | E12: 21297.91 | F12: 21704.97 | H12: De | I12: =L12*'R.trabajo y honorarios'!$H$74 | J12: a | K12: =O12*'R.trabajo y honorarios'!$H$74 | L12: 651 | M12: UVT | N12: Y | O12: 9999 | P12: 0 | R12: A restar | S12: =S6-S9 | T12: Limite ingresos | U12: ='R.trabajo y honorarios'!H4*25% | V12: ='R.trabajo y honorarios'!L4*25% | W12: ='R.capital'!G2*25% | X12: ='R.no laboral y R gravables'!G3*25%
B13: 1962 | C13: 2688.94 | D13: 20800.81 | E13: 20154.38 | F13: 20539.58 | R13: Aportes voluntarios - honorarios | T13: Limite UVT | U13: ='R.trabajo y honorarios'!H74*2500 | V13: =U13 | W13: =U13 | X13: =W13
B14: 1963 | C14: 2511.5 | D14: 19429.21 | E14: 18825.4 | F14: 19185.21 | I14: Salario mensual | K14: ='R.trabajo y honorarios'!H3 | R14: Limite 3.800 UVT | S14: =S6 | T14: Valor reportad | U14: ='R.trabajo y honorarios'!F24 | V14: ='R.trabajo y honorarios'!J24 | W14: ='R.capital'!E40 | X14: ='R.no laboral y R gravables'!E24
B15: 1964 | C15: 1920.42 | D15: 14857.22 | E15: 14395.49 | F15: 14670.63 | I15: Cesantias | K15: ='R.trabajo y honorarios'!F52+'R.trabajo y honorarios'!F53+'R.trabajo y honorarios'!F54 | R15: Limite ingresos | S15: ='R.trabajo y honorarios'!L4*30% | U15: =MIN(U12,U13,U14) | V15: =MIN(V12,V13,V14) | W15: =MIN(W12,W13,W14) | X15: =MIN(X12,X13,X14)
B16: 1965 | C16: 1758.11 | D16: 13600.8 | E16: 13178.13 | F16: 13429.99 | K16: =K15*P8 | R16: Valor reportado | S16: ='R.trabajo y honorarios'!J50+'R.trabajo y honorarios'!J51 | T16: A resultar | U16: =U13-U15
B17: 1966 | C17: 1533.84 | D17: 11865.93 | E17: 11497.16 | F17: 11716.9 | R17: Valor a reportar | S17: =MIN(S14:S16) | T17: Condicional 2 | V17: =MIN(U16,V15)
B18: 1967 | C18: 1352.33 | D18: 10462.43 | E18: 10137.28 | F18: 10331.03 | I18: ='R.trabajo y honorarios'!C52 | K18: ='R.trabajo y honorarios'!F52 | L18: =K18/$K$21 | R18: FINAL DE HONORARIOS | S18: =MIN(S12,S17)
B19: 1968 | C19: 1255.75 | D19: 9714.61 | E19: 9412.7 | F19: 9592.6 | I19: ='R.trabajo y honorarios'!C53 | K19: ='R.trabajo y honorarios'!F53 | L19: =K19/$K$21
B20: 1969 | C20: 1178.09 | D20: 9113.87 | E20: 8830.63 | F20: 8999.41 | I20: ='R.trabajo y honorarios'!C54 | K20: ='R.trabajo y honorarios'!F54 | L20: =K20/$K$21 | R20: Aportes voluntarios - Renta de capital
B21: 1970 | C21: 1083.26 | D21: 8380.22 | E21: 8119.79 | F21: 8274.98 | I21: TOTAL | K21: =SUM(K18:K20) | R21: Limite 3.800 UVT | S21: =S14 | AA21: Ingresos brutos anuales | AC21: Ingresos brutos anuales | AE21: Tarifa marginal | AF21: CALCULO | AG21: BASE CEDULA GENERAL Y PENSIÓN | AH21: IMPUESTO
B22: 1971 | C22: 1011.41 | D22: 7823.78 | E22: 7580.64 | F22: 7725.53 | R22: Limite ingresos | S22: ='R.capital'!G2*30% | AA22: Igual o superior | AB22: Igual o superior | AC22: Inferior
B23: 1972 | C23: 896.22 | D23: 6934.19 | E23: 6718.7 | F23: 6847.11 | I23: LIMITE | K23: ='R.trabajo y honorarios'!G52 | R23: Valor reportado | S23: ='R.capital'!E53+'R.capital'!E54 | AA23: 0 | AB23: 1090 | AC23: =AA23*Sheet1!$F$2 | AD23: =AB23*Sheet1!$F$2 | AE23: 0 | AF23: 0 | AG23: =#REF! | AH23: 0
B24: 1973 | C24: 788.01 | D24: 6097.77 | E24: 5908.26 | F24: 6021.19 | I24: =I18 | K24: =L18*$K$23 | R24: VALOR A REPORTAR | S24: =MIN(S21:S23) | AA24: =AB23+1 | AB24: 1700 | AC24: =AA24*Sheet1!$F$2 | AD24: =AB24*Sheet1!$F$2 | AE24: 0.19 | AF24: (Base gravable en UVT Menos 1090 UVT) *19% | AG24: =#REF! | AH24: =(((AG24/Sheet1!$F$2)-1090)*19%)*Sheet1!AE11
B25: 1974 | C25: 643.73 | D25: 4981.35 | E25: 4826.54 | F25: 4918.79 | I25: =I19 | K25: =L19*$K$23 | AA25: =AB24+1 | AB25: 4100 | AC25: =AA25*Sheet1!$F$2 | AD25: =AB25*Sheet1!$F$2 | AE25: 0.28 | AF25: (Base gravable en UVT Menos 1700 UVT) *28% + 116 UVT | AG25: =#REF! | AH25: =((((AG25/Sheet1!$F$2)-1700)*28%)+116)*Sheet1!$F$2
B26: 1975 | C26: 514.87 | D26: 3981.89 | E26: 3858.14 | F26: 3931.88 | I26: =I20 | K26: =L20*$K$23 | R26: Aportes voluntarios - No laborales | AA26: =AB25+1 | AB26: 8670 | AC26: =AA26*Sheet1!$F$2 | AD26: =AB26*Sheet1!$F$2 | AE26: 0.33 | AF26: (Base gravable en UVT Menos 4100 UVT) *33% + 788 UVT | AG26: =#REF! | AH26: =((((AG26/Sheet1!$F$2)-4100)*33%)+788)*Sheet1!$F$2
B27: 1976 | C27: 437.78 | D27: 3385.47 | E27: 3281.22 | F27: 3343.94 | R27: Limite 3.800 UVT | S27: =S14 | AA27: =AB26+1 | AB27: 18970 | AC27: =AA27*Sheet1!$F$2 | AD27: =AB27*Sheet1!$F$2 | AE27: 0.35 | AF27: (Base gravable en UVT Menos 8670 UVT) *35% + 2296 UVT | AG27: =#REF! | AH27: =((((AG27/Sheet1!$F$2)-8670)*35%)+2296)*Sheet1!$F$2
B28: 1977 | C28: 349.06 | D28: 2698.9 | E28: 2615.02 | F28: 2665 | R28: Limite ingresos | S28: ='R.no laboral y R gravables'!G3*30% | AA28: =AB27+1 | AB28: 31000 | AC28: =AA28*Sheet1!$F$2 | AD28: =AB28*Sheet1!$F$2 | AE28: 0.37 | AF28: (Base gravable en UVT Menos 18970 UVT) *37% + 5901 UVT | AG28: =#REF! | AH28: =((((AG28/Sheet1!$F$2)-18970)*37%)+5901)*Sheet1!$F$2
B29: 1978 | C29: 273.72 | D29: 2117.65 | E29: 2051.84 | F29: 2091.05 | R29: Valor reportado | S29: ='R.no laboral y R gravables'!E64+'R.no laboral y R gravables'!E65 | AA29: =AB28+1 | AB29: En adelante | AC29: =AA29*Sheet1!$F$2 | AD29: 9999999999 | AE29: 0.39 | AF29: (Base gravable en UVT Menos 31000 UVT) *39% - 10352 UVT | AG29: =#REF! | AH29: =((((AG29/Sheet1!$F$2)-31000)*39%)+10352)*Sheet1!$F$2
B30: 1979 | C30: 228.64 | D30: 1768.55 | E30: 1713.59 | F30: 1746.34 | K30: Limite aportes voluntarios cesantias (Renta capital) | L30: Limite aportes voluntarios cesantias (Renta no laboral) | R30: VALOR A REPORTAR | S30: =MIN(S27:S29)
B31: 1980 | C31: 180.64 | D31: 1398.18 | E31: 1354.73 | F31: 1380.62 | K31: ='R.capital'!G2/12 | L31: ='R.no laboral y R gravables'!G3*25% | AE31: Renta cedula | AF31: =IF(AND(Sheet1!AG23>Sheet1!AC23,Sheet1!AG23<Sheet1!AD23),Sheet1!AH23,IF(AND(Sheet1!AG24>Sheet1!AC24,Sheet1!AG24<Sheet1!AD24),Sheet1!AH24,IF(AND(Sheet1!AG25>Sheet1!AC25,Sheet1!AG25<Sheet1!AD25),Sheet1!AH25,IF(AND(Sheet1!AG26>Sheet1!AC26,Sheet1!AG26<Sheet1!AD26),Sheet1!AH26,IF(AND(Sheet1!AG27>Sheet1!AC27,Sheet1!AG27<Sheet1!AD27),Sheet1!AH27,IF(AND(Sheet1!AG28>Sheet1!AC28,Sheet1!AG28<Sheet1!AD28),Sheet1!AH28,IF(AND(Sheet1!AG29>Sheet1!AC29,Sheet1!AG29<Sheet1!AD29),Sheet1!AH29,0)))))))
B32: 1981 | C32: 145.15 | D32: 1121.73 | E32: 1086.87 | F32: 1107.65 | K32: =2500*'R.capital'!G68 | L32: ='R.no laboral y R gravables'!G87*2500
B33: 1982 | C33: 115.48 | D33: 893.13 | E33: 865.38 | F33: 881.92 | K33: =MIN(K31,K32) | L33: =MIN(L31,L32)
B34: 1983 | C34: 92.79 | D34: 717.7 | E34: 695.39 | F34: 708.68
B35: 1984 | C35: 79.7 | D35: 616.69 | E35: 597.52 | F35: 608.94
B36: 1985 | C36: 67.49 | D36: 535.17 | E36: 518.54 | F36: 528.45
B37: 1986 | C37: 55.27 | D37: 443.02 | E37: 429.25 | F37: 437.46
B38: 1987 | C38: 45.67 | D38: 375.68 | E38: 364.01 | F38: 370.97
B39: 1988 | C39: 37.23 | D39: 283.53 | E39: 274.72 | F39: 279.97
B40: 1989 | C40: 29.17 | D40: 176.77 | E40: 171.27 | F40: 174.55
B41: 1990 | C41: 23.14 | D41: 122.25 | E41: 118.45 | F41: 120.71
B42: 1991 | C42: 17.54 | D42: 85.19 | E42: 82.54 | F42: 84.12 | I42: Limite deducciones
...

Sheet Deudas
A1: DEUDAS
A2: Renglón 30 | D2: =ROUND(SUM(C2:C41),-3)

Sheet R.trabajo y honorarios
B1: RENTAS DE TRABAJO Y/O HONORARIOS
C2: Concepto | G2: Rentas de trabajo | I2: Renglón 43 | J2: Rentas por honorarios y comp. Serv. Personales sujetos a costos y gastos y no renta exenta num. 10 Art. 206 E.T.
C3: Indique el valor del salario mensual promedio de los últimos 6 meses (numeral 4 Art. 206 E.T.) | H3: =G4/12
C4: Salarios | G4: 0 | H4: =ROUND(SUM(G4:G19),-3) | L4: =ROUND(SUM(J9:K19),-3)
C5: Bonificaciones, indemnizaciones, y otros ingresos salariales
C6: Cesantías consignadas | G6: 0
C7: Intereses sobre cesantías
C8: Cesantías 2016 y anteriores
C9: Honorarios | J9: 0 | M9: =+G9*0.25
C10: Comisiones
C11: Servicios personales
C12: Otros laborales y prestaciones sociales | G12: 0
B20: INCRNGO
C21: Aporte obligatorio a pensión | G21: 0 | H21: =ROUND(SUM(G21:G32),-3) | I21: Renglón 44 | L21: =J22+K24+J25+J26+J27+J28+J29+J30+J31+J32
C22: Bonos de alimentacion
C23: Aporte obligatorio a salud | G23: 0
C24: Aporte voluntario a fondo obligatorio porvenir - RAIS | G24: =Sheet1!U15 | K24: =Sheet1!V17
C25: Aporte obligatorio a pension como independiente | J25: 0
C26: Aporte obligatorio a salud como independiente
C27: Aporte A.R.L. NO TIENE EFECTO FISCAL
C28: Salarios funcionarios de organismos multilaterales
C29: Salarios y/o honorarios vinculados proyectos de investigación (Art. 57-2 E.T.)
C30: Apoyos ecónomicos (Art 46 E.T.)
B33: Costos y deducciones
H34: 0 | I34: Renglón 45 | L34: =ROUND(MIN(SUM(J34:K47),K9),-3)
C36: Costos honorarios | J36: 0
C48: Total rentas exentas y deducciones | H48: =SUM(H34:H47) | L48: =SUM(L34)
B49: Rentas exentas y deducciones
C50: Aporte voluntario a pension | F50: 0 | G50: 0 | H50: =ROUND(SUM(G50:G67),-3) | I50: R. 47 | K50: 0 | L50: =ROUND(SUM(K52:K67),-3)
C51: Ahorro en cuenta AFC y/o AVC
C52: Cesantías consignadas | F52: 0 | G52: 0 | I52: Renglón 48
C53: Intereses sobre cesantías | F53: =G7
C54: Retiro de cesantias antes del año 2016 (Ley 1819 del 2016) No limitada | F54: =G8
C55: Indemizaciones por accidente de trabajo (Numeral 1. Art. 206 E.T.)
C56: Indemizaciones por protección a maternidad (Numeral 2. Art. 206 E.T.)
C57: Gastos de entierro (Numeral 3. Art. 206 E.T.)
C58: Seguro por muerte, compensaciones por muerte y prestaciones sociales de FFMM. (Numeral 6 Art. 206 E.T.). No limitada
C59: Exceso de salario fuerzas militares. (Numeral 8 Art. 206 E.T.). No limitada
C60: Gastos de representación rectores y profesores universidades publicas. (Numeral 9 Art. 206 E.T.). No limitada
C61: Prima especial y prima de costo de vida servidores publicos - Diplomaticos. ( Art. 206-1 E.T.). No limitada
...

Sheet Dependientes 
B3: Número de dependientes | C3: 0 | D3: Sólo digite el número de dependientes
B4: Deducción adicional individual por dependiente | C4: 3585528
B6: Nombre del dependiente económico | C6: Deducción
C7: {=_xlfn.IFS(C3=1,C4,C3=2,C4,C3=3,C4,C3=4,C4,C3=0,0)}
C8: {=0+_xlfn.IFS(C3=2,C4,C3=3,C4,C3=4,C4,C3=1,0,C3=0,0)}
C9: {=0+_xlfn.IFS(C3=1,0,C3=2,0,C3=3,C4,C3=4,C4,C3=0,0)}
C10: {=0+_xlfn.IFS(C3=1,0,C3=2,0,C3=3,0,C3=4,C4,C3=0,0)}
B11: Total Duducción Adicional | C11: =ROUND(SUM(C7:C10),-3)
D12: 3585528
B14: La deducción por dependientes a que se refieren el inciso 2 del numeral 3 del artículo 336 y la del artículo 387 del Estatuto Tributario aplican únicamente a los ingresos provenientes de rentas de trabajo y un mismo dependiente solo dará lugar a una de estas dos deducciones, excepto cuando se tenga rentas provenientes de una relación laboral y legal o reglamentaria: caso en el cual se podrá aplicar ambas deducciones por un mismo dependiente."

Sheet Fac. Elctrónicas
B2: No factura | C2: Valor factura incluido IVA | D2: Derecho deducción. | E2: 5. Las personas naturales que declaren ingresos de la cédula general a los que se refiere el artículo 335 de este Estatuto, que adquieran bienes y/o servicios, podrán solicitar como deducción en el impuesto sobre la renta, independientemente que tenga o no relación de causalidad con la actividad productora de renta del contribuyente, el uno por ciento (1%) del valor de las adquisiciones, sin que exceda doscientas cuarenta (240) UVT en el respectivo año gravable, siempre que se cumpla con los siguientes requisitos: 5.1. Que la adquisición del bien y/o del servicio no haya sido solicitada como costo o deducción en el impuesto sobre la renta, impuesto descontable en el impuesto sobre las ventas -IVA, ingreso no constitutivo de renta ni ganancia ocasional, renta exenta, descuento tributario u otro tipo de beneficio o crédito fiscal. 5.2. Que la adquisición del bien y/o del servicio esté soportada con factura electrónica de venta con validación previa, en donde se identifique el adquirente con nombres y apellidos y el número de identificación tributaria -NIT o número de documento de identificación, y con el cumplimiento de todos los demás requisitos exigibles para este sistema de facturación. 5.3. Que la factura electrónica de venta se encuentre pagada a través de tarjeta débito/crédito o cualquier medio electrónico en el cual intervenga una entidad vigilada por la Superintendencia Financiera o quien haga sus veces dentro del periodo gravable en el cual se solicita la deducción de que trata el presente numeral. 5.4. Que la factura electrónica de venta haya sido expedida por sujetos obligados a expedirla.
D3: =C3*1%
D4: =C4*1%
D5: =C5*1%
D6: =C6*1%
D7: =C7*1%
D8: =C8*1%
D9: =C9*1%
D10: =C10*1%
D11: =C11*1%
D12: =C12*1%
D13: =C13*1%
D14: =C14*1%
... D26: =C26*1%
B27: TOTAL 1% COMPRAS REALIZADAS | D27: =SUM(D3:D26)
B28: LÍMITE (Art 336 Numeral 5 - 240 UVT) | D28: =(240*49065)
B29: Deducción a tomar | D29: =MIN(D27:D28)

Sheet R.capital
B1: RENTAS DE CAPITAL
B2: Rengón 58 | C2: Rendimientos financieros con componente inflacionario | G2: =ROUND((F3+F13+F21+F29),-3)
F3: =SUM(E3:E11)
C12: Intereses de fuente nacional y del exterior
F13: =SUM(E13:E19)
C19: Ingresos presuntos | E19: ='tabl int presunt'!G18
C20: Arrendamientos
F21: =SUM(E21:E27)
C28: Regalias y propiedad intelectual
F29: =SUM(E29:E35)
B36: Renglón 59 | C36: I.N.C.R.N.G.O.
C37: Aporte obligatorio a pensión | G37: =ROUND(SUM(F37:F43),-3)
C38: Aporte obligatorio a salud
C39: Aporte obligatorio a A.R.L.
C40: Aporte voluntario a fondo obligatorio - RAIS | F40: =Sheet1!W15
C41: Componente inflacionario | F41: =F3*55.43%
B44: Renglón 60 | C44: Costos y gastos procedentes
G45: =ROUND(SUM(F45:F51),-3)
C52: Rentas exentas y deducciones
B53: R.63 | C53: Aporte voluntario a pensión | F53: =Sheet1!S24 | G53: =SUM(F55:F57)
C54: Ahorro en cuenta AFC y/o AVC
B55: R. 66 | C55: Intereses por prestamos de vivienda | E55: 0 | F55: =IF(E55>(1200*G68),(1200*G68),E55)
B56: R.67 | C56: G.M.F. | F56: =E56*50%
C57: Aportes voluntarios a fondos de cesantias | F57: =IF(E57>Sheet1!K33,Sheet1!K33,E57)
B58: Renglón 62 | C58: Rentas líquidas pasivas de capital
G59: =ROUND(SUM(F59:F63),-3)
B65: R. 72 | C65: Compensaciones por pérdidas
C66: Compensación de perdidas | G66: =F66
C68: Valor UVT | G68: ='R.trabajo y honorarios'!H74

Sheet tabl int presunt
B1: CÁLCULO DEL INTERES PRESUNTO
B2: DECRETO 771 12 JULIO DE 2025
B3: Rend. Mínimo | G3: 0.0925
B4: Mensual | G4: =G3/12
B5: Mes | C5: Saldo Inicial | D5: Nuevo Préstamo | E5: Abonos | F5: Saldo Final | G5: Int. Presunto
B6: Enero | C6: 0 | F6: =C6+D6-E6 | G6: =C6*$G$4
B7: Febrero | C7: =F6 | F7: =C7+D7-E7 | G7: =C7*$G$4
B8: Marzo | C8: =F7 | F8: =C8+D8-E8 | G8: =C8*$G$4
B9: Abril | C9: =F8 | D9: 0 | F9: =C9+D9-E9 | G9: =C9*$G$4
B10: Mayo | C10: =F9 | D10: 0 | F10: =C10+D10-E10 | G10: =C10*$G$4
B11: Junio | C11: =F10 | F11: =C11+D11-E11 | G11: =C11*$G$4
B12: Julio | C12: =F11 | F12: =C12+D12-E12 | G12: =C12*$G$4
B13: Agosto | C13: =F12 | F13: =C13+D13-E13 | G13: =C13*$G$4
B14: Septiembre | C14: =F13 | F14: =C14+D14-E14 | G14: =C14*$G$4
B15: Octubre | C15: =F14 | F15: =C15+D15-E15 | G15: =C15*$G$4
B16: Noviembre | C16: =F15 | F16: =C16+D16-E16 | G16: =C16*$G$4
B17: Diciembre | C17: =F16 | F17: =C17+D17-E17 | G17: =C17*$G$4
B18: Total intereses presunto | G18: =SUM(G6:G17)

Sheet R.no laboral y R gravables
B1: Renglón 74 | C1: RENTAS NO LABORALES
C2: Ingresos
G3: =ROUND(SUM(F3:F16),-3)
B17: Renglón 75 | C17: Devoluciones, rebajas y descuentos
G18: =ROUND(SUM(F18:F22),-3)
B23: Renglón 76 | C23: I.N.C.R.N.G.O.
C24: Aporte voluntario a fondo obligatorio - RAIS | F24: =Sheet1!X15 | G24: =ROUND(SUM(F24:F36),-3)
C25: Aporte obligatorio a salud
C26: Aporte Obligatorio a Pensión
C27: Aporte riesgo laboral
C28: Seguro de daño componente daño emergente | F28: =F6
C29: Ganancial liquid sociedad conyugal art. 47 E.T. | F29: =F4
B37: Renglón 77 | C37: Costos y gastos procedentes
G38: =SUM(F38:F56)
B57: Renglón 79 | C57: Rentas líquidas pasivas no laborales E.C.E
G58: 0
B63: Rentas exentas y deducciones
B64: R. 80 | C64: Aporte voluntario a pensión | F64: =Sheet1!S30 | G64: =SUM(F66:F71)
C65: Ahorro en cuenta AFC y/o AVC
B66: R. 81 | C66: Rentas por servicios hoteleros en nuevos o remodelados (No limitada)
C67: Otras rentas exentas
B69: R. 83 | C69: Intereses por prestamos de vivienda | F69: =IF(E69>(1200*G87),(1200*G87),E69)
B70: R. 84 | C70: G.M.F. | F70: =E70/2
C71: Aportes voluntarios a fondos de cesantias | F71: =IF(E71>Sheet1!L33,Sheet1!L33,E71)
B72: Renglón 79 | C72: Rentas líquidas pasivas de capital
G73: =ROUND(SUM(F73:F77),-3)
B79: R. 89 | C79: Compensaciones por pérdidas
C80: Compensación de perdidas | G80: =F80
B82: Renglón 96 | C82: Rentas liquidas gravables Art 239-1 y otras
C83: Activos omitidos | G83: =SUM(F83:F85)
C84: Pasivos inexistentes
C85: Diferencia por comparación patrimonial no justificada
B87: Valor UVT | G87: ='R.capital'!G68

Sheet G.OCAS
A1: GANANCIA OCASIONAL
A2: Renglón 111 | B2: Venta de inmuebles diferente a vivienda | C2: Tipo de inmueble/ Acciones | D2: Precio de venta | E2: Costo fiscal por ganancia ocasional
E3: Costo Fiscal año anterior (Avaluo catastral o autoavaluo art. 72 E.T.) | G3: =IF(ROUND(SUM(F3+F7+F8+F9),-3)>D3,D3,ROUND(SUM(F3+F7+F8+F9),-3)) | H3: Diligencie esta sección solo si en año anterior el VALOR PATRIMONIAL fue determinado con el valor del predial o si desea determinar el costo de la ganancia ocasional con el valor de compra más reajustes fiscales
E4: Costo de adquisición
E5: Fecha de compra
E6: Fecha de venta
E7: Costo fiscal reajustado | F7: =+'REAJUST FISCAL'!F57
E8: (+) mejoras en el año de la venta
E9: (+) Valorización en el año de la venta
E10: Costo de adquisición | G10: =IF(ROUND(SUM(F14+F15+F16),-3)>D3,D3,ROUND(SUM(F14+F15+F16),-3)) | H10: Diligencie esta sección solo si en año anterior el valor patrimonial lo determino de acuerdo al art. 73 E.T.
E11: Bines raices o acciones o aportes | F11: Bienes urbanos
E12: Año de adquisición | F12: 2001
E13: Ajuste incremento porcentual del v/r. de la propiedad raíz entre el año de la compra y el año de la venta | F13: =IF(G.OCAS!F11="Acciones y aportes",VLOOKUP(G.OCAS!F12,Sheet1!$B$5:$F$75,2),IF(G.OCAS!F11="BIENES URBANOS",VLOOKUP(G.OCAS!F12,Sheet1!$B$5:$F$75,3),IF(G.OCAS!F11="BIENES RURALES",VLOOKUP(G.OCAS!F12,Sheet1!$B$5:$F$75,5),IF(G.OCAS!F11="Bienes Raíces Rurales dedicados a actividades agropecuarias",VLOOKUP(G.OCAS!F12,Sheet1!$B$5:$F$75,4),0))))
E14: Costo reajustado | F14: =+F10*G.OCAS!F13
E15: (+) mejoras
E16: (+) Valorización
E17: Costo Fiscal año anterior (Avaluo catastral o autoavaluo art. 72 E.T.) | G17: =IF(ROUND(SUM(F17+F21+F22+F23),-3)>D17,D17,ROUND(SUM(F17+F21+F22+F23),-3)) | H17: Diligencie esta sección solo si en año anterior el VALOR PATRIMONIAL fue determinado con el valor del predial o si desea determinar el costo de la ganancia ocasional con el valor de compra más reajustes fiscales
E18: Costo de adquisición
E19: Fecha de compra
E20: Fecha de venta
E21: Costo fiscal reajustado | F21: =+'REAJUST FISCAL'!F117
E22: (+) mejoras en el año de la venta
E23: (+) Valorización en el año de la venta
E24: Costo de adquisición | G24: =IF(ROUND(SUM(F28+F29+F30),-3)>D17,D17,ROUND(SUM(F28+F29+F30),-3)) | H24: Diligencie esta sección solo si en año anterior el valor patrimonial lo determino de acuerdo al art. 73 E.T.
E25: Bines raices o acciones o aportes | F25: Bienes urbanos
E26: Año de adquisición | F26: 2021
E27: Ajuste incremento porcentual del v/r. de la propiedad raíz entre el año de la compra y el año de la venta | F27: =IF(G.OCAS!F25="Acciones y aportes",VLOOKUP(G.OCAS!F26,Sheet1!$B$5:$F$75,2),IF(G.OCAS!F25="BIENES URBANOS",VLOOKUP(G.OCAS!F26,Sheet1!$B$5:$F$75,3),IF(G.OCAS!F25="BIENES RURALES",VLOOKUP(G.OCAS!F26,Sheet1!$B$5:$F$75,5),IF(G.OCAS!F25="Bienes Raíces Rurales dedicados a actividades agropecuarias",VLOOKUP(G.OCAS!F26,Sheet1!$B$5:$F$75,4),0))))
E28: Costo reajustado | F28: =+F24*F27
E29: (+) mejoras
E30: (+) Valorización
B31: Venta casa habitación | C31: 0 | D31: 0 | E31: Costo Fiscal año anterior (Avaluo catastral o autoavaluo art. 72 E.T.) | F31: 0 | G31: =IF(ROUND(SUM(F31+F35+F36+F37),-3)>D31,D31,ROUND(SUM(F31+F35+F36+F37),-3)) | H31: Diligencie esta sección solo si en año anterior el VALOR PATRIMONIAL fue determinado con el valor del predial o si desea determinar el costo de la ganancia ocasional con el valor de compra más reajustes fiscales
E32: Costo de adquisición | F32: 0
E33: Fecha de compra | F33: 44576
E34: Fecha de venta | F34: 45321
E35: Costo fiscal reajustado
E36: (+) mejoras en el año de la venta
E37: (+) Valorización en el año de la venta
E38: Costo de adquisición | F38: 0 | G38: =IF(ROUND(SUM(F42+F43+F44),-3)>D31,D31,ROUND(SUM(F42+F43+F44),-3)) | H38: Diligencie esta sección solo si en año anterior el valor patrimonial lo determino de acuerdo al art. 73 E.T.
E39: Bines raices o acciones o aportes | F39: Bienes urbanos
E40: Año de adquisición | F40: 2021
...

Sheet REAJUST FISCAL
B4: AÑO | C4: % | D4: VALOR BASE | E4: REAJUSTE | F4: TOTAL REAJUSTADO | G4: Normatividad
B5: 1974 | C5: 0.08 | D5: =+IF(B5='REAJUST FISCAL'!$I$11,G.OCAS!$F$4,0) | E5: =+IF(B5=$I$11,C5*$M$11*D5,IF(B5=$I$12,C5*$M$12*D5,C5*D5)) | F5: =+'REAJUST FISCAL'!D5+E5 | G5: Decreto 2247 de 1974
B6: 1975 | C6: 0.08 | D6: =+IF(B6='REAJUST FISCAL'!$I$11,G.OCAS!$F$4,F5) | E6: =+IF(B6=$I$11,C6*$M$11*D6,IF(B6=$I$12,C6*$M$12*D6,C6*D6)) | F6: =+D6+E6 | G6: Decreto 187 de 1975
B7: 1976 | C7: 0.08 | D7: =+IF(B7='REAJUST FISCAL'!$I$11,G.OCAS!$F$4,F6) | E7: =+IF(B7=$I$11,C7*$M$11*D7,IF(B7=$I$12,C7*$M$12*D7,C7*D7)) | F7: =+D7+E7 | G7: Ley 19 de 1976
B8: 1977 | C8: 0.14 | D8: =+IF(B8='REAJUST FISCAL'!$I$11,G.OCAS!$F$4,F7) | E8: =+IF(B8=$I$11,C8*$M$11*D8,IF(B8=$I$12,C8*$M$12*D8,C8*D8)) | F8: =+D8+E8 | G8: Ley 54 de 1977
B9: 1978 | C9: 0.095 | D9: =+IF(B9='REAJUST FISCAL'!$I$11,G.OCAS!$F$4,F8) | E9: =+IF(B9=$I$11,C9*$M$11*D9,IF(B9=$I$12,C9*$M$12*D9,C9*D9)) | F9: =+D9+E9 | G9: Decreto 2114 de 1978
B10: 1979 | C10: 0.244 | D10: =+IF(B10='REAJUST FISCAL'!$I$11,G.OCAS!$F$4,F9) | E10: =+IF(B10=$I$11,C10*$M$11*D10,IF(B10=$I$12,C10*$M$12*D10,C10*D10)) | F10: =+D10+E10 | G10: Ley 20 de 1979 /Decreto 2326 de 1979
B11: 1980 | C11: 0.2472 | D11: =+IF(B11='REAJUST FISCAL'!$I$11,G.OCAS!$F$4,F10) | E11: =+IF(B11=$I$11,C11*$M$11*D11,IF(B11=$I$12,C11*$M$12*D11,C11*D11)) | F11: =+D11+E11 | G11: Decreto 2534 de 1980 | I11: =+YEAR(G.OCAS!F5) | J11: =+CONCATENATE("31/12/",+I11) | K11: 360 | L11: =+_xlfn.DAYS(J11,G.OCAS!F5) | M11: =+L11/K11 | N11: =+M11*C50
B12: 1981 | C12: 0.2775 | D12: =+IF(B12='REAJUST FISCAL'!$I$11,G.OCAS!$F$4,F11) | E12: =+IF(B12=$I$11,C12*$M$11*D12,IF(B12=$I$12,C12*$M$12*D12,C12*D12)) | F12: =+D12+E12 | G12: Decreto 2655 de 1981 | I12: =+YEAR(G.OCAS!F6) | J12: 45292 | K12: 360 | L12: =+_xlfn.DAYS(G.OCAS!F6,J12) | M12: =+L12/K12
B13: 1982 | C13: 0.2347 | D13: =+IF(B13='REAJUST FISCAL'!$I$11,G.OCAS!$F$4,F12) | E13: =+IF(B13=$I$11,C13*$M$11*D13,IF(B13=$I$12,C13*$M$12*D13,C13*D13)) | F13: =+D13+E13 | G13: Decreto 2809 de 1982
B14: 1983 | C14: 0.1942 | D14: =+IF(B14='REAJUST FISCAL'!$I$11,G.OCAS!$F$4,F13) | E14: =+IF(B14=$I$11,C14*$M$11*D14,IF(B14=$I$12,C14*$M$12*D14,C14*D14)) | F14: =+D14+E14 | G14: Ley 9 de 1983/Decreto 2124 de 1983
B15: 1984 | C15: 0.1517 | D15: =+IF(B15='REAJUST FISCAL'!$I$11,G.OCAS!$F$4,F14) | E15: =+IF(B15=$I$11,C15*$M$11*D15,IF(B15=$I$12,C15*$M$12*D15,C15*D15)) | F15: =+D15+E15 | G15: Decreto 1843 de 1984
B16: 1985 | C16: 0.2451 | D16: =+IF(B16='REAJUST FISCAL'!$I$11,G.OCAS!$F$4,F15) | E16: =+IF(B16=$I$11,C16*$M$11*D16,IF(B16=$I$12,C16*$M$12*D16,C16*D16)) | F16: =+D16+E16 | G16: Decreto 2032 de 1985
B17: 1986 | C17: 0.163 | D17: =+IF(B17='REAJUST FISCAL'!$I$11,G.OCAS!$F$4,F16) | E17: =+IF(B17=$I$11,C17*$M$11*D17,IF(B17=$I$12,C17*$M$12*D17,C17*D17)) | F17: =+D17+E17 | G17: Ley 75 de 1986/Decreto 2444 de 1986
B18: 1987 | C18: 0.1679 | D18: =+IF(B18='REAJUST FISCAL'!$I$11,G.OCAS!$F$4,F17) | E18: =+IF(B18=$I$11,C18*$M$11*D18,IF(B18=$I$12,C18*$M$12*D18,C18*D18)) | F18: =+D18+E18 | G18: Decreto 59 de 1987
B19: 1988 | C19: 0.2365 | D19: =+IF(B19='REAJUST FISCAL'!$I$11,G.OCAS!$F$4,F18) | E19: =+IF(B19=$I$11,C19*$M$11*D19,IF(B19=$I$12,C19*$M$12*D19,C19*D19)) | F19: =+D19+E19 | G19: Decreto 2540 de 1987
B20: 1989 | C20: 0.2799 | D20: =+IF(B20='REAJUST FISCAL'!$I$11,G.OCAS!$F$4,F19) | E20: =+IF(B20=$I$11,C20*$M$11*D20,IF(B20=$I$12,C20*$M$12*D20,C20*D20)) | F20: =+D20+E20 | G20: Decreto 2671 de 1988
B21: 1990 | C21: 0.2664 | D21: =+IF(B21='REAJUST FISCAL'!$I$11,G.OCAS!$F$4,F20) | E21: =+IF(B21=$I$11,C21*$M$11*D21,IF(B21=$I$12,C21*$M$12*D21,C21*D21)) | F21: =+D21+E21 | G21: Decreto 624 de 1989 / Decreto 3018 de 1989
B22: 1991 | C22: 0.3004 | D22: =+IF(B22='REAJUST FISCAL'!$I$11,G.OCAS!$F$4,F21) | E22: =+IF(B22=$I$11,C22*$M$11*D22,IF(B22=$I$12,C22*$M$12*D22,C22*D22)) | F22: =+D22+E22 | G22: Decreto 3100 de 1990
B23: 1992 | C23: 0.2981 | D23: =+IF(B23='REAJUST FISCAL'!$I$11,G.OCAS!$F$4,F22) | E23: =+IF(B23=$I$11,C23*$M$11*D23,IF(B23=$I$12,C23*$M$12*D23,C23*D23)) | F23: =+D23+E23 | G23: Certificación DANE 102300
B24: 1993 | C24: 0.262 | D24: =+IF(B24='REAJUST FISCAL'!$I$11,G.OCAS!$F$4,F23) | E24: =+IF(B24=$I$11,C24*$M$11*D24,IF(B24=$I$12,C24*$M$12*D24,C24*D24)) | F24: =+D24+E24 | G24: Certificación DANE 102294
... B31: 2000 | C31: 0.0936 | D31: =+IF(B31='REAJUST FISCAL'!$I$11,G.OCAS!$F$4,F30) | E31: =+IF(B31=$I$11,C31*$M$11*D31,IF(B31=$I$12,C31*$M$12*D31,C31*D31)) | F31: =+D31+E31 | G31: Decreto 0333 de 2001
B32: 2001 | C32: 0.0896 | D32: =+IF(B32='REAJUST FISCAL'!$I$11,G.OCAS!$F$4,F31) | E32: =+IF(B32=$I$11,C32*$M$11*D32,IF(B32=$I$12,C32*$M$12*D32,C32*D32)) | F32: =+D32+E32 | G32: Decreto 00406 de 2002 | I32: =+D32*C32
B33: 2002 | C33: 0.06 | D33: =+IF(B33='REAJUST FISCAL'!$I$11,G.OCAS!$F$4,F32) | E33: =+IF(B33=$I$11,C33*$M$11*D33,IF(B33=$I$12,C33*$M$12*D33,C33*D33)) | F33: =+D33+E33 | G33: Decreto 3257 de 2002 | I33: =+D33*C33
B34: 2003 | C34: 0.06 | D34: =+IF(B34='REAJUST FISCAL'!$I$11,G.OCAS!$F$4,F33) | E34: =+IF(B34=$I$11,C34*$M$11*D34,IF(B34=$I$12,C34*$M$12*D34,C34*D34)) | F34: =+D34+E34 | G34: Decreto 03804 de 2003 | I34: =+D34*C34
B35: 2004 | C35: 0.0695 | D35: =+IF(B35='REAJUST FISCAL'!$I$11,G.OCAS!$F$4,F34) | E35: =+IF(B35=$I$11,C35*$M$11*D35,IF(B35=$I$12,C35*$M$12*D35,C35*D35)) | F35: =+D35+E35 | G35: Decreto 4344 de 2003 | I35: =+D35*C35
B36: 2005 | C36: 0.061 | D36: =+IF(B36='REAJUST FISCAL'!$I$11,G.OCAS!$F$4,F35) | E36: =+IF(B36=$I$11,C36*$M$11*D36,IF(B36=$I$12,C36*$M$12*D36,C36*D36)) | F36: =+D36+E36 | G36: Decreto 4715 de 2005 | I36: =+D36*C36
B37: 2006 | C37: 0.0487 | D37: =+IF(B37='REAJUST FISCAL'!$I$11,G.OCAS!$F$4,F36) | E37: =+IF(B37=$I$11,C37*$M$11*D37,IF(B37=$I$12,C37*$M$12*D37,C37*D37)) | F37: =+D37+E37 | G37: Res. 15652 de 2006 | I37: =+D37*C37
B38: 2007 | C38: 0.0515 | D38: =+IF(B38='REAJUST FISCAL'!$I$11,G.OCAS!$F$4,F37) | E38: =+IF(B38=$I$11,C38*$M$11*D38,IF(B38=$I$12,C38*$M$12*D38,C38*D38)) | F38: =+D38+E38 | G38: Res. 15013 de 2007 | I38: =+D38*C38
B39: 2008 | C39: 0.0775 | D39: =+IF(B39='REAJUST FISCAL'!$I$11,G.OCAS!$F$4,F38) | E39: =+IF(B39=$I$11,C39*$M$11*D39,IF(B39=$I$12,C39*$M$12*D39,C39*D39)) | F39: =+D39+E39 | G39: Decreto 4715 de 2008
B40: 2009 | C40: 0.0333 | D40: =+IF(B40='REAJUST FISCAL'!$I$11,G.OCAS!$F$4,F39) | E40: =+IF(B40=$I$11,C40*$M$11*D40,IF(B40=$I$12,C40*$M$12*D40,C40*D40)) | F40: =+D40+E40 | G40: Decreto 4930 de 2009 | I40: =+D40*C40
B41: 2010 | C41: 0.0235 | D41: =+IF(B41='REAJUST FISCAL'!$I$11,G.OCAS!$F$4,F40) | E41: =+IF(B41=$I$11,C41*$M$11*D41,IF(B41=$I$12,C41*$M$12*D41,C41*D41)) | F41: =+D41+E41 | G41: Decreto 4837 de 2010 | I41: =+D41*C41
B42: 2011 | C42: 0.0365 | D42: =+IF(B42='REAJUST FISCAL'!$I$11,G.OCAS!$F$4,F41) | E42: =+IF(B42=$I$11,C42*$M$11*D42,IF(B42=$I$12,C42*$M$12*D42,C42*D42)) | F42: =+D42+E42 | G42: Decreto 4908 de 2011 | I42: =+D42*C42
B43: 2012 | C43: 0.0304 | D43: =+IF(B43='REAJUST FISCAL'!$I$11,G.OCAS!$F$4,F42) | E43: =+IF(B43=$I$11,C43*$M$11*D43,IF(B43=$I$12,C43*$M$12*D43,C43*D43)) | F43: =+D43+E43 | G43: Decreto 2714 de 2012 | I43: =+D43*C43
B44: 2013 | C44: 0.024 | D44: =+IF(B44='REAJUST FISCAL'!$I$11,G.OCAS!$F$4,F43) | E44: =+IF(B44=$I$11,C44*$M$11*D44,IF(B44=$I$12,C44*$M$12*D44,C44*D44)) | F44: =+D44+E44 | G44: Decreto 2921 de 2013 | I44: =+D44*C44
B45: 2014 | C45: 0.0289 | D45: =+IF(B45='REAJUST FISCAL'!$I$11,G.OCAS!$F$4,F44) | E45: =+IF(B45=$I$11,C45*$M$11*D45,IF(B45=$I$12,C45*$M$12*D45,C45*D45)) | F45: =+D45+E45 | G45: Decreto 2624 de 2014 | I45: =+D45*C45
B46: 2015 | C46: 0.0521 | D46: =+IF(B46='REAJUST FISCAL'!$I$11,G.OCAS!$F$4,F45) | E46: =+IF(B46=$I$11,C46*$M$11*D46,IF(B46=$I$12,C46*$M$12*D46,C46*D46)) | F46: =+D46+E46 | G46: Decreto 2453 de 2015 | I46: =+D46*C46
B47: 2016 | C47: 0.0708 | D47: =+IF(B47='REAJUST FISCAL'!$I$11,G.OCAS!$F$4,F46) | E47: =+IF(B47=$I$11,C47*$M$11*D47,IF(B47=$I$12,C47*$M$12*D47,C47*D47)) | F47: =+D47+E47 | G47: Decreto 2202 de 2016 | I47: =+D47*C47
B48: 2017 | C48: 0.0407 | D48: =+IF(B48='REAJUST FISCAL'!$I$11,G.OCAS!$F$4,F47) | E48: =+IF(B48=$I$11,C48*$M$11*D48,IF(B48=$I$12,C48*$M$12*D48,C48*D48)) | F48: =+D48+E48 | G48: Decreto 2169 de 2017 | I48: =+D48*C48
B49: 2018 | C49: 0.0407 | D49: =+IF(B49='REAJUST FISCAL'!$I$11,G.OCAS!$F$4,F48) | E49: =+IF(B49=$I$11,C49*$M$11*D49,IF(B49=$I$12,C49*$M$12*D49,C49*D49)) | F49: =+D49+E49 | G49: Decreto 2391 de 2018 | I49: =+D49*C49
...

Sheet C.pensiones
B1: RENTAS DE PENSIONES
B2: Renglón 99 | C2: De fuente nacional y de fuente extranjera | F2: =ROUND(SUM(E9+E16),-3)
C3: Porvenir
C4: Colpensiones
C5: Estados Unidos
C6: Indemnizacion sustitutiva o devolucion de saldos
C9: Total ingresos por pensiones - fuente nacional | E9: =SUM(E3:E8)
C10: De fuente extranjera
C16: Total ingresos por pensiones - fuente extranjera | E16: =SUM(E11:E15)
B17: Renglón 100 | C17: I.N.C.R.N.G.O.
F18: =ROUND(SUM(E18:E24),-3)
C19: aporte a salud
B25: Renglón 102 | C25: Rentas exentas
C26: Renta exenta pensinoes de Colombia de fuente Nacional | E26: 0 | F26: 0

Sheet renta presunt
B2: RENTA PRESUNTIVA
B4: Total patrimonio bruto 2024 | E4: 0
B5: Deudas | E5: 0
B6: Patrimonio líquido 2024 | E6: =(E4-E5)
B7: Menos: patrimonio excluido
B8: % Valor Patrimonial | E8: =IFERROR(E6/E4,0)
B9: V/r. de las acciones en sociedades nacionales | D9: 0 | E9: =D9*$E$8
B10: V/r. del total de los activos destinados a empresas en periodo improductivo | D10: 0 | E10: =D10*$E$8
B11: V/r. de los activos afectados por fuerza mayor o caso fortuito | D11: 0 | E11: =D11*$E$8
B12: Las primeras 8.000 UVT Casa habitación | D12: 0 | E12: =IF(D12>265248000,265248000,D12)
B13: Las primeras 19.000 UVT activos destinados sector agropecuario | E13: =IF(D13>605321000,605321000,D13)
B14: Total base renta presuntiva | E14: =E6-E9-E12
B15: Renta presuntiva Inicial | D15: 0 | E15: =ROUND((E14*D15),-3)
B16: Más: ingresos gravados generados por los activos excluídos - Divid. gravados | E16: 0
B17: Total renta presuntiva depurada | E17: =ROUND(SUM(E15:E16),-3)

Sheet C divid.
B1: RENTAS POR DIVIDENDOS Y PARTICIPACIONES
B2: Renglon 104 | C2: Dividendos y participaciones 2016, anteriores y otros
F3: =ROUND(SUM(E3:E9),-3)
C4: Dividendos no gravados
C5: Dividendos gravados
B10: Renglon 105 | C10: I.N.C.R.N.G.O.
F11: =ROUND(SUM(E11:E15),-3)
C12: Dividendos no gravados | E12: =E4
B16: Renglon 107 | C16: 1a. Subcédula año 2017 y siguientes numeral 3. Art 49 del E.T.
F17: =ROUND(SUM(E17:E23),-3)
C18: Dividendos no gravados
B24: Renglon 108 | C24: 2a Subcedula año 2017 y siguientes (parágrafo 2 Art. 49)
F25: =ROUND(SUM(E25:E31),-3)
C26: Dividendos gravados
B32: Renglon 109 | C32: Renta líquida pasiva dividendos - E.C.E.
F33: =ROUND(SUM(E33:E39),-3)
B40: Renglon 110 | C40: Rentas exentas de la casilla 110
F41: =ROUND(SUM(E41:E47),-3)

Sheet impto renta
A2: Valor UVT año 2023 | E2: 49799 | H2: R.L.C.GENERAL | I2: ='FORMULARIO 210'!J46
H3: Renta presuntiva | I3: ='FORMULARIO 210'!AA33
H4: Renta liq pension | I4: ='FORMULARIO 210'!J38
H5: Total | I5: =SUM(I3:I4)
A7: Ingresos brutos anuales | C7: Ingresos brutos anuales | E7: Tarifa marginal | F7: CALCULO | G7: BASE CEDULA GENERAL Y PENSIÓN | H7: IMPUESTO | I7: BASE RENTA PRESUNTIVA Y PENSIÓN | J7: IMPUESTO
A8: Igual o superior | B8: Igual o superior | C8: Inferior
A9: 0 | B9: 1090 | C9: =A9*$E$2 | D9: =B9*$E$2 | E9: 0 | F9: 0 | G9: ='FORMULARIO 210'!J46 | H9: 0 | I9: =IF(I5>I2,I5,0) | J9: 0
A10: =B9+1 | B10: 1700 | C10: =A10*$E$2 | D10: =B10*$E$2 | E10: 0.19 | F10: (Base gravable en UVT Menos 1090 UVT) *19% | G10: =$G$9 | H10: =(((G10/$E$2)-1090)*19%)*E2 | I10: =$I$9 | J10: =(((I10/$E$2)-1090)*19%)*E2
A11: =B10+1 | B11: 4100 | C11: =A11*$E$2 | D11: =B11*$E$2 | E11: 0.28 | F11: (Base gravable en UVT Menos 1700 UVT) *28% + 116 UVT | G11: =$G$9 | H11: =((((G11/$E$2)-1700)*28%)+116)*$E$2 | I11: =$I$9 | J11: =((((I11/$E$2)-1700)*28%)+116)*$E$2
A12: =B11+1 | B12: 8670 | C12: =A12*$E$2 | D12: =B12*$E$2 | E12: 0.33 | F12: (Base gravable en UVT Menos 4100 UVT) *33% + 788 UVT | G12: =$G$9 | H12: =((((G12/$E$2)-4100)*33%)+788)*$E$2 | I12: =$I$9 | J12: =((((I12/$E$2)-4100)*33%)+788)*$E$2
A13: =B12+1 | B13: 18970 | C13: =A13*$E$2 | D13: =B13*$E$2 | E13: 0.35 | F13: (Base gravable en UVT Menos 8670 UVT) *35% + 2296 UVT | G13: =$G$9 | H13: =((((G13/$E$2)-8670)*35%)+2296)*$E$2 | I13: =$I$9 | J13: =((((I13/$E$2)-8670)*35%)+2296)*$E$2
A14: =B13+1 | B14: 31000 | C14: =A14*$E$2 | D14: =B14*$E$2 | E14: 0.37 | F14: (Base gravable en UVT Menos 18970 UVT) *37% + 5901 UVT | G14: =$G$9 | H14: =((((G14/$E$2)-18970)*37%)+5901)*$E$2 | I14: =$I$9 | J14: =((((I14/$E$2)-18970)*37%)+5901)*$E$2
A15: =B14+1 | B15: En adelante | C15: =A15*$E$2 | D15: 9999999999 | E15: 0.39 | F15: (Base gravable en UVT Menos 31000 UVT) *39% - 10352 UVT | G15: =$G$9 | H15: =((((G15/$E$2)-31000)*39%)+10352)*$E$2 | I15: =$I$9 | J15: =((((I15/$E$2)-31000)*39%)+10352)*$E$2
A17: Renta cedula general + pensión | E17: =ROUND(IF(AND('impto renta'!G9>'impto renta'!C9,'impto renta'!G9<'impto renta'!D9),'impto renta'!H9,IF(AND('impto renta'!G10>'impto renta'!C10,'impto renta'!G10<'impto renta'!D10),'impto renta'!H10,IF(AND('impto renta'!G11>'impto renta'!C11,'impto renta'!G11<'impto renta'!D11),'impto renta'!H11,IF(AND('impto renta'!G12>'impto renta'!C12,'impto renta'!G12<'impto renta'!D12),'impto renta'!H12,IF(AND('impto renta'!G13>'impto renta'!C13,'impto renta'!G13<'impto renta'!D13),'impto renta'!H13,IF(AND('impto renta'!G14>'impto renta'!C14,'impto renta'!G14<'impto renta'!D14),'impto renta'!H14,IF(AND('impto renta'!G15>'impto renta'!C15,'impto renta'!G15<'impto renta'!D15),'impto renta'!H15,0))))))),-3)
A18: renta presentiva renta + pensión | E18: =ROUND(IF(AND('impto renta'!I9>'impto renta'!C9,'impto renta'!I9<'impto renta'!D9),'impto renta'!J9,IF(AND('impto renta'!I10>'impto renta'!C10,'impto renta'!I10<'impto renta'!D10),'impto renta'!J10,IF(AND('impto renta'!I11>'impto renta'!C11,'impto renta'!I11<'impto renta'!D11),'impto renta'!J11,IF(AND('impto renta'!I12>'impto renta'!C12,'impto renta'!I12<'impto renta'!D12),'impto renta'!J12,IF(AND('impto renta'!I13>'impto renta'!C13,'impto renta'!I13<'impto renta'!D13),'impto renta'!J13,IF(AND('impto renta'!I14>'impto renta'!C14,'impto renta'!I14<'impto renta'!D14),'impto renta'!J14,IF(AND('impto renta'!I15>'impto renta'!C15,'impto renta'!I15<'impto renta'!D15),'impto renta'!J15,0))))))),-3)
A23: Por dividendos y participaciones año 2016 (base casilla 76)
A24: Renta líquida sobre dividendos gravados 2016 y anteriores | E24: ='FORMULARIO 210'!J41
A25: En UVT | E25: =E24/$E$2
A26: Valor del impuesto de renta | E26: =MAX(E31:E34)
A29: Rangos en UVT | C29: Tarifa marginal | D29: Impuesto | E29: IMPUESTO SOBRE LA RENTA POR DIVIDENDOS 2016 Y ANTERIORES
A30: Desde | B30: Hasta
A31: >0 | B31: 1090 | C31: 0 | D31: 0 | E31: 0
A32: >1,090 | B32: 1700 | C32: 0.19 | D32: (Base gravable en UVT menos 1.090 UVT) X 19% | E32: =IF(E25>1090,(IF(E25<=1700,ROUND((((+E25-1090)*19%)*E2),-3),0)),0)
A33: >1,700 | B33: 4100 | C33: 0.28 | D33: (Base gravable en UVT menos 1.700 UVT) X 28% + 116 UVT | E33: =IF(E25>1700,IF(E25<=4100,ROUND((((+E25-1700)*28%)*E2)+(116*E2),-3),0),0)
A34: >4,100 | B34: En adelante | C34: 0.33 | D34: (Base gravable en UVT menos 4.100 UVT) X 33% + 788 UVT | E34: =IF(E25>4100,ROUND((((+E25-4100)*33%)*E2)+(788*E2),-3),0)
A37: Valor primera subcedula Renglón 107 | E37: ='FORMULARIO 210'!J42
A38: En UVT | E38: 0
A39: Valor del impuesto en pesos | E39: =ROUND(MAX(E43:E44),-3)
A41: Rangos en UVT | C41: Tarifa marginal | D41: Impuesto | E41: Determinación del impuesto de renta primera subcédula | F41: Determinación del impuesto de renta segunda subcédula
A42: Desde | B42: Hasta
A43: >0 | B43: 300 | C43: 0 | D43: 0 | E43: 0 | F43: 0
A44: >300 | B44: en Adelante | C44: 0.1 | D44: (Dividendos en UVT menos 300 UVT) X 10% | E44: =IF(E38>300,((E38-300)*10%)*E2,0) | F44: =IF(E49>300,((E49-300)*10%)*E2,0)
A46: Valor segunda subcédula (Renglones 108) | E46: ='FORMULARIO 210'!J43
A47: Valor primera parte del impuesto 35% | E47: =E46*0.35
A48: Subtotal | E48: =E46-E47
A49: En UVT | E49: 0
A50: Valor segunda parte del impuesto | E50: 0
A51: Valor total impuesto segunda subcédula | E51: =ROUND((E50+E47),-3)

Sheet dtos tribut
B2: Por impuesto Pagados en el Exterior | E2: =ROUND(SUM(D3:D5),-3)
B6: Por Donaciones | E6: =ROUND(SUM(D7:D9),-3)
D7: =C7*0.25
D8: =C8*0.25
D9: =C9*0.25
B10: Otros descuentos tributarios | E10: =ROUND(SUM(D11:D13),-3)
B14: Descuento dividendos
B15: Por dividendos no gravados y exceso sobre los gravados 2017 y siguientes | E15: =MAX(0,ROUND((((('C divid.'!F17+'C divid.'!F25-'FORMULARIO 210'!Y36)/'impto renta'!E2)-1090)*19%)*'impto renta'!E2,-3))
B20: Descuento por impuestos pagados en el exterior por ganancias ocasionales | E20: =ROUND(SUM(D21:D23),-3)

Sheet retefuente
B1: RETENCIONES EN LA FUENTE QUE LE PRACTICARON
C2: Agente retenedor | D2: Valor | E2: Total
B3: Renglón 133 | E3: =ROUND(SUM(D3:D36),-3)

Sheet anticipo
B1: CÁLCULO DEL ANTICIPO DE RENTA POR EL AÑO GRAVABLE 2025
C3: Registre el valor del saldo a favor no solicitado en devolución casilla 138 declaración renta 2024 | E3: 0
C4: Registre el valor del anticipo para la renta 2025, registrado en la casilla 134 declaración renta año 2024 | E4: 0
B5: Renglón 134 | C5: Registre el valor del impuesto neto de renta registrado en la casilla 127 declaración renta año 2024 | E5: 0
C6: Para el anticipo digite: 1 declaración por primera vez; 2 declaración por segunda vez; 3 declara por tercera y siguientes años; 4 declaración del año corriente es la última que presenta. | E6: 3
C7: Primer año | D7: Impuesto neto de renta año corriente | E7: {='FORMULARIO 210'!Y42:AB42} | F7: 0 | G7: 0 | H7: 0
D8: 0.25 | E8: =ROUND(+E7*D8,-3)
D9: Menos: retenciones en la fuente | E9: =retefuente!E3
D10: Total anticipo para el año 2026 | E10: =IF(E6=1,IF(E8-E9>0,E8-E9,0),0)
C11: Segundo año | D11: 1) Método del promedio
D12: Impuesto neto de renta año anterior | E12: =+E5
D13: =D7 | E13: =+E7
D14: Subtotal | E14: =+E12+E13
D15: Promedio | E15: =ROUND(+E14/2,-3)
D16: 0.5 | E16: =ROUND(+E15*D16,-3)
D17: Menos: Retenciones en la fuente | E17: =+E9
D18: Anticipo método del promedio | E18: =IF(E6=2,IF(E16-E17>0,E16-E17,0),0)
D19: 2) Método directo
D20: =D13 | E20: =+E7
D21: 0.5 | E21: =ROUND(+E20*D21,-3)
D22: Menos: retenciones en la fuente | E22: =+E9
D23: Anticipo método directo | E23: =IF(E6=2,IF(E21-E22>0,E21-E22,0),0)
D24: Total anticipo para el año 2026 | E24: =IF(E18>E23,E23,E18)
C25: Tercer y siguientes años | D25: 1) Método del promedio
D26: Impuesto neto de renta año anterior | E26: =+E5
D27: =D20 | E27: =+E7
